It starts a try block. If an Exception is thrown inside a try block, the Exception will be compared to any of the catch part of the block. If the Exception matches with one of the Exceptions in the catch part, the exception will be handled there.